Workbook

Sheet 거래내역
A1: 일자 | B1: 구분 | C1: 항목 | D1: 적요 | E1: 입금 | F1: 출금 | G1: 잔액
A2: 45903 | B2: 출금 | C2: 기타 | D2: 클라우드 서버 이용료 | F2: 686418 | G2: ='월별 요약'!$B$3+N(E2)-N(F2) -> 81313582
A3: 45905 | B3: 출금 | C3: 임차료 | D3: 사무실 임차료 | F3: 1500000 | G3: =G2+N(E3)-N(F3) -> 79813582
A4: 45905 | B4: 출금 | C4: 임차료 | D4: 사무실 관리비 | F4: 240000 | G4: =G3+N(E4)-N(F4) -> 79573582
A5: 45907 | B5: 출금 | C5: 기타 | D5: 협업 SaaS 구독 (메신저·문서·저장소) | F5: 320000 | G5: =G4+N(E5)-N(F5) -> 79253582
A6: 45908 | B6: 입금 | C6: 매출 | D6: [프로젝트] A사 커머스 고도화 잔금 | E6: 14300000 | G6: =G5+N(E6)-N(F6) -> 93553582
A7: 45910 | B7: 출금 | C7: 보험 | D7: 4대보험 납부 (회사·근로자분) | F7: 2250000 | G7: =G6+N(E7)-N(F7) -> 91303582
A8: 45910 | B8: 출금 | C8: 세금공과 | D8: 원천세·지방소득세 납부 | F8: 480000 | G8: =G7+N(E8)-N(F8) -> 90823582
A9: 45912 | B9: 출금 | C9: 기타 | D9: 통신비 (인터넷·휴대폰) | F9: 118000 | G9: =G8+N(E9)-N(F9) -> 90705582
A10: 45915 | B10: 출금 | C10: 마케팅 | D10: 온라인 광고비 (검색·SNS) | F10: 1328551 | G10: =G9+N(E10)-N(F10) -> 89377031
A11: 45917 | B11: 출금 | C11: 보험 | D11: 영업배상책임보험 연납 | F11: 480000 | G11: =G10+N(E11)-N(F11) -> 88897031
A12: 45918 | B12: 출금 | C12: 매입/원재료 | D12: 개발 소프트웨어 라이선스·소모품 | F12: 496506 | G12: =G11+N(E12)-N(F12) -> 88400525
A13: 45925 | B13: 출금 | C13: 인건비 | D13: 급여 지급 (4명, 실수령) | F13: 11600000 | G13: =G12+N(E13)-N(F13) -> 76800525
A14: 45928 | B14: 출금 | C14: 기타 | D14: 식대·복리후생 | F14: 611098 | G14: =G13+N(E14)-N(F14) -> 76189427
A15: 45930 | B15: 입금 | C15: 매출 | D15: [유지보수] 월 정액 (3개사) | E15: 3300000 | G15: =G14+N(E15)-N(F15) -> 79489427
A16: 45933 | B16: 출금 | C16: 기타 | D16: 클라우드 서버 이용료 | F16: 595106 | G16: =G15+N(E16)-N(F16) -> 78894321
A17: 45935 | B17: 출금 | C17: 임차료 | D17: 사무실 임차료 | F17: 1500000 | G17: =G16+N(E17)-N(F17) -> 77394321
A18: 45935 | B18: 출금 | C18: 임차료 | D18: 사무실 관리비 | F18: 250000 | G18: =G17+N(E18)-N(F18) -> 77144321
A19: 45937 | B19: 출금 | C19: 기타 | D19: 협업 SaaS 구독 (메신저·문서·저장소) | F19: 320000 | G19: =G18+N(E19)-N(F19) -> 76824321
A20: 45940 | B20: 출금 | C20: 보험 | D20: 4대보험 납부 (회사·근로자분) | F20: 2250000 | G20: =G19+N(E20)-N(F20) -> 74574321
A21: 45940 | B21: 출금 | C21: 세금공과 | D21: 원천세·지방소득세 납부 | F21: 480000 | G21: =G20+N(E21)-N(F21) -> 74094321
A22: 45942 | B22: 출금 | C22: 기타 | D22: 통신비 (인터넷·휴대폰) | F22: 118000 | G22: =G21+N(E22)-N(F22) -> 73976321
A23: 45944 | B23: 입금 | C23: 매출 | D23: [프로젝트] B사 ERP 연동 계약금 | E23: 9900000 | G23: =G22+N(E23)-N(F23) -> 83876321
A24: 45945 | B24: 출금 | C24: 마케팅 | D24: 온라인 광고비 (검색·SNS) | F24: 1470280 | G24: =G23+N(E24)-N(F24) -> 82406041
A25: 45948 | B25: 출금 | C25: 매입/원재료 | D25: 개발 소프트웨어 라이선스·소모품 | F25: 609067 | G25: =G24+N(E25)-N(F25) -> 81796974
A26: 45952 | B26: 출금 | C26: 외주 | D26: UI 디자인 외주 | F26: 2800000 | G26: =G25+N(E26)-N(F26) -> 78996974
A27: 45955 | B27: 출금 | C27: 세금공과 | D27: 부가가치세 신고·납부 | F27: 2640000 | G27: =G26+N(E27)-N(F27) -> 76356974
A28: 45955 | B28: 출금 | C28: 인건비 | D28: 급여 지급 (4명, 실수령) | F28: 11600000 | G28: =G27+N(E28)-N(F28) -> 64756974
A29: 45958 | B29: 입금 | C29: 매출 | D29: [프로젝트] C사 관리자 대시보드 중도금 | E29: 12100000 | G29: =G28+N(E29)-N(F29) -> 76856974
A30: 45958 | B30: 출금 | C30: 기타 | D30: 식대·복리후생 | F30: 652324 | G30: =G29+N(E30)-N(F30) -> 76204650
A31: 45960 | B31: 입금 | C31: 매출 | D31: [유지보수] 월 정액 (3개사) | E31: 3300000 | G31: =G30+N(E31)-N(F31) -> 79504650
A32: 45964 | B32: 출금 | C32: 기타 | D32: 클라우드 서버 이용료 | F32: 615477 | G32: =G31+N(E32)-N(F32) -> 78889173
A33: 45966 | B33: 출금 | C33: 임차료 | D33: 사무실 임차료 | F33: 1500000 | G33: =G32+N(E33)-N(F33) -> 77389173
A34: 45966 | B34: 출금 | C34: 임차료 | D34: 사무실 관리비 | F34: 230000 | G34: =G33+N(E34)-N(F34) -> 77159173
A35: 45967 | B35: 출금 | C35: 장비 | D35: 개발용 노트북 2대 | F35: 3640000 | G35: =G34+N(E35)-N(F35) -> 73519173
A36: 45968 | B36: 출금 | C36: 기타 | D36: 협업 SaaS 구독 (메신저·문서·저장소) | F36: 320000 | G36: =G35+N(E36)-N(F36) -> 73199173
A37: 45971 | B37: 출금 | C37: 보험 | D37: 4대보험 납부 (회사·근로자분) | F37: 2250000 | G37: =G36+N(E37)-N(F37) -> 70949173
A38: 45971 | B38: 출금 | C38: 세금공과 | D38: 원천세·지방소득세 납부 | F38: 480000 | G38: =G37+N(E38)-N(F38) -> 70469173
A39: 45973 | B39: 출금 | C39: 기타 | D39: 통신비 (인터넷·휴대폰) | F39: 118000 | G39: =G38+N(E39)-N(F39) -> 70351173
A40: 45976 | B40: 출금 | C40: 마케팅 | D40: 온라인 광고비 (검색·SNS) | F40: 1319130 | G40: =G39+N(E40)-N(F40) -> 69032043
...

Sheet 월별 요약
A1: 월별 현금흐름 요약 (단위: 원)
A2: 거래내역 시트를 SUMIFS로 집계합니다. 노란 셀만 입력값이고 나머지는 전부 수식입니다.
A3: 기초 잔액 (2025-09-01, 입력값 · 가상) | B3: 82000000 | C3: ← 브릿지 「현금흐름 진단」의 기초 잔액 입력칸에 이 값을 넣으세요
A4: 월 | B4: 시작일 | C4: 종료일 | D4: 입금 합계 | E4: 출금 합계 | F4: 순현금흐름 | G4: 월말 잔액
A5: 2025-09 | B5: 45901 | C5: 45930 | D5: =SUMIFS(거래내역!$E$2:$E$184,거래내역!$A$2:$A$184,">="&B5,거래내역!$A$2:$A$184,"<="&C5) -> 17600000 | E5: =SUMIFS(거래내역!$F$2:$F$184,거래내역!$A$2:$A$184,">="&B5,거래내역!$A$2:$A$184,"<="&C5) -> 20110573 | F5: =D5-E5 -> -2510573 | G5: =$B$3+F5 -> 79489427
A6: 2025-10 | B6: 45931 | C6: 45961 | D6: =SUMIFS(거래내역!$E$2:$E$184,거래내역!$A$2:$A$184,">="&B6,거래내역!$A$2:$A$184,"<="&C6) -> 25300000 | E6: =SUMIFS(거래내역!$F$2:$F$184,거래내역!$A$2:$A$184,">="&B6,거래내역!$A$2:$A$184,"<="&C6) -> 25284777 | F6: =D6-E6 -> 15223 | G6: =G5+F6 -> 79504650
A7: 2025-11 | B7: 45962 | C7: 45991 | D7: =SUMIFS(거래내역!$E$2:$E$184,거래내역!$A$2:$A$184,">="&B7,거래내역!$A$2:$A$184,"<="&C7) -> 22000000 | E7: =SUMIFS(거래내역!$F$2:$F$184,거래내역!$A$2:$A$184,">="&B7,거래내역!$A$2:$A$184,"<="&C7) -> 23314604 | F7: =D7-E7 -> -1314604 | G7: =G6+F7 -> 78190046
A8: 2025-12 | B8: 45992 | C8: 46022 | D8: =SUMIFS(거래내역!$E$2:$E$184,거래내역!$A$2:$A$184,">="&B8,거래내역!$A$2:$A$184,"<="&C8) -> 36319632 | E8: =SUMIFS(거래내역!$F$2:$F$184,거래내역!$A$2:$A$184,">="&B8,거래내역!$A$2:$A$184,"<="&C8) -> 21335205 | F8: =D8-E8 -> 14984427 | G8: =G7+F8 -> 93174473
A9: 2026-01 | B9: 46023 | C9: 46053 | D9: =SUMIFS(거래내역!$E$2:$E$184,거래내역!$A$2:$A$184,">="&B9,거래내역!$A$2:$A$184,"<="&C9) -> 23100000 | E9: =SUMIFS(거래내역!$F$2:$F$184,거래내역!$A$2:$A$184,">="&B9,거래내역!$A$2:$A$184,"<="&C9) -> 22711067 | F9: =D9-E9 -> 388933 | G9: =G8+F9 -> 93563406
A10: 2026-02 | B10: 46054 | C10: 46081 | D10: =SUMIFS(거래내역!$E$2:$E$184,거래내역!$A$2:$A$184,">="&B10,거래내역!$A$2:$A$184,"<="&C10) -> 31800000 | E10: =SUMIFS(거래내역!$F$2:$F$184,거래내역!$A$2:$A$184,">="&B10,거래내역!$A$2:$A$184,"<="&C10) -> 20565608 | F10: =D10-E10 -> 11234392 | G10: =G9+F10 -> 104797798
A11: 2026-03 | B11: 46082 | C11: 46112 | D11: =SUMIFS(거래내역!$E$2:$E$184,거래내역!$A$2:$A$184,">="&B11,거래내역!$A$2:$A$184,"<="&C11) -> 23116428 | E11: =SUMIFS(거래내역!$F$2:$F$184,거래내역!$A$2:$A$184,">="&B11,거래내역!$A$2:$A$184,"<="&C11) -> 21882013 | F11: =D11-E11 -> 1234415 | G11: =G10+F11 -> 106032213
A12: 2026-04 | B12: 46113 | C12: 46142 | D12: =SUMIFS(거래내역!$E$2:$E$184,거래내역!$A$2:$A$184,">="&B12,거래내역!$A$2:$A$184,"<="&C12) -> 22000000 | E12: =SUMIFS(거래내역!$F$2:$F$184,거래내역!$A$2:$A$184,">="&B12,거래내역!$A$2:$A$184,"<="&C12) -> 27746677 | F12: =D12-E12 -> -5746677 | G12: =G11+F12 -> 100285536
A13: 2026-05 | B13: 46143 | C13: 46173 | D13: =SUMIFS(거래내역!$E$2:$E$184,거래내역!$A$2:$A$184,">="&B13,거래내역!$A$2:$A$184,"<="&C13) -> 14300000 | E13: =SUMIFS(거래내역!$F$2:$F$184,거래내역!$A$2:$A$184,">="&B13,거래내역!$A$2:$A$184,"<="&C13) -> 22166289 | F13: =D13-E13 -> -7866289 | G13: =G12+F13 -> 92419247
A14: 2026-06 | B14: 46174 | C14: 46203 | D14: =SUMIFS(거래내역!$E$2:$E$184,거래내역!$A$2:$A$184,">="&B14,거래내역!$A$2:$A$184,"<="&C14) -> 11014554 | E14: =SUMIFS(거래내역!$F$2:$F$184,거래내역!$A$2:$A$184,">="&B14,거래내역!$A$2:$A$184,"<="&C14) -> 22473419 | F14: =D14-E14 -> -11458865 | G14: =G13+F14 -> 80960382
A15: 2026-07 | B15: 46204 | C15: 46234 | D15: =SUMIFS(거래내역!$E$2:$E$184,거래내역!$A$2:$A$184,">="&B15,거래내역!$A$2:$A$184,"<="&C15) -> 9900000 | E15: =SUMIFS(거래내역!$F$2:$F$184,거래내역!$A$2:$A$184,">="&B15,거래내역!$A$2:$A$184,"<="&C15) -> 25144563 | F15: =D15-E15 -> -15244563 | G15: =G14+F15 -> 65715819
A16: 2026-08 | B16: 46235 | C16: 46265 | D16: =SUMIFS(거래내역!$E$2:$E$184,거래내역!$A$2:$A$184,">="&B16,거래내역!$A$2:$A$184,"<="&C16) -> 11000000 | E16: =SUMIFS(거래내역!$F$2:$F$184,거래내역!$A$2:$A$184,">="&B16,거래내역!$A$2:$A$184,"<="&C16) -> 22422523 | F16: =D16-E16 -> -11422523 | G16: =G15+F16 -> 54293296
A17: 합계 | D17: =SUM(D5:D16) -> 247450614 | E17: =SUM(E5:E16) -> 275157318 | F17: =SUM(F5:F16) -> -27706704
A18: 핵심 지표
A19: 현재 잔액 (거래내역 마지막 잔액) | B19: =거래내역!G184 -> 54293296
A20: 최근 3개월 평균 순현금흐름 | B20: =AVERAGE(F14:F16) -> -12708650
A21: 월평균 순유출(번레이트) | B21: =IF(B20<0,-B20,0) -> 12708650
A22: 런웨이 (개월) | B22: =IF(B21>0,ROUND(B19/B21,1),"해당 없음") -> 4.3
A23: 건강도 (규칙) | B23: =IF(ISNUMBER(B22),IF(B22<3,"위험",IF(B22<6,"주의","안정")),"안정") -> 주의
A24: 런웨이 기준 (개월) | B24: 위험 <3 · 주의 <6 · 안정 ≥6
A25: ※ 런웨이 = 현재 잔액 ÷ 최근 3개월 평균 순유출. 순유입이면 "해당 없음". 판단 기준(3/6개월)은 브릿지 PRD §15.3의 healthByRule과 동일.
A27: 최근 3개월 출금 항목별 비중
A28: 항목 | B28: 출금 합계 | C28: 비중
A29: 인건비 | B29: =SUMIFS(거래내역!$F$2:$F$184,거래내역!$C$2:$C$184,A29,거래내역!$A$2:$A$184,">="&$B$14,거래내역!$A$2:$A$184,"<="&$C$16) -> 37584000 | C29: =IF($B$38=0,0,B29/$B$38) -> 0.53660378
A30: 임차료 | B30: =SUMIFS(거래내역!$F$2:$F$184,거래내역!$C$2:$C$184,A30,거래내역!$A$2:$A$184,">="&$B$14,거래내역!$A$2:$A$184,"<="&$C$16) -> 5190000 | C30: =IF($B$38=0,0,B30/$B$38) -> 0.07409998
A31: 매입/원재료 | B31: =SUMIFS(거래내역!$F$2:$F$184,거래내역!$C$2:$C$184,A31,거래내역!$A$2:$A$184,">="&$B$14,거래내역!$A$2:$A$184,"<="&$C$16) -> 1614230 | C31: =IF($B$38=0,0,B31/$B$38) -> 0.023047093
A32: 마케팅 | B32: =SUMIFS(거래내역!$F$2:$F$184,거래내역!$C$2:$C$184,A32,거래내역!$A$2:$A$184,">="&$B$14,거래내역!$A$2:$A$184,"<="&$C$16) -> 8583190 | C32: =IF($B$38=0,0,B32/$B$38) -> 0.12254609
A33: 세금공과 | B33: =SUMIFS(거래내역!$F$2:$F$184,거래내역!$C$2:$C$184,A33,거래내역!$A$2:$A$184,">="&$B$14,거래내역!$A$2:$A$184,"<="&$C$16) -> 2926500 | C33: =IF($B$38=0,0,B33/$B$38) -> 0.041782965
A34: 보험 | B34: =SUMIFS(거래내역!$F$2:$F$184,거래내역!$C$2:$C$184,A34,거래내역!$A$2:$A$184,">="&$B$14,거래내역!$A$2:$A$184,"<="&$C$16) -> 7290000 | C34: =IF($B$38=0,0,B34/$B$38) -> 0.10408263
A35: 외주 | B35: =SUMIFS(거래내역!$F$2:$F$184,거래내역!$C$2:$C$184,A35,거래내역!$A$2:$A$184,">="&$B$14,거래내역!$A$2:$A$184,"<="&$C$16) -> 1650000 | C35: =IF($B$38=0,0,B35/$B$38) -> 0.023557797
A36: 장비 | B36: =SUMIFS(거래내역!$F$2:$F$184,거래내역!$C$2:$C$184,A36,거래내역!$A$2:$A$184,">="&$B$14,거래내역!$A$2:$A$184,"<="&$C$16) -> 0 | C36: =IF($B$38=0,0,B36/$B$38) -> 0
A37: 기타 | B37: =SUMIFS(거래내역!$F$2:$F$184,거래내역!$C$2:$C$184,A37,거래내역!$A$2:$A$184,">="&$B$14,거래내역!$A$2:$A$184,"<="&$C$16) -> 5202585 | C37: =IF($B$38=0,0,B37/$B$38) -> 0.074279661
A38: 합계 | B38: =SUM(B29:B37) -> 70040505 | C38: =SUM(C29:C37) -> 1

Sheet 안내
A1: 가상 기업 현금흐름표 — 합성 데이터
A3: 이 파일은 「브릿지(Bridge)」 현금흐름 진단 기능(PRD §15.3) 시연용으로 만든 가상 기업의 합성 데이터입니다. 실제 기업·거래와 무관합니다.
A5: 가상 기업 프로필 (브릿지 데모 프로필 ①과 동일)
A6: · 업종: 소프트웨어 개발업 (KSIC J62) · 지역: 광주광역시 · 법인 · 상시근로자 4명 · 업력 약 3년
A7: · 기간: 2025-09-01 ~ 2026-08-31 (12개월) · 기초 잔액 8,200만원 (월별 요약!B3, 노란 셀 — 브릿지 화면의 기초 잔액 칸에도 82000000 입력)
A9: 스토리 (데이터에 심어 둔 패턴)
A10: · 2025-09 ~ 2026-04: 프로젝트 대금 + 유지보수 3개사 월정액으로 안정. 2026-02 지원사업 1차 지원금 1,200만원 입금(가상).
A11: · 2026-03: 연봉 8% 인상 → 인건비·원천세·4대보험 상승.
A12: · 2026-05: 주요 고객 2개사 이탈 → 유지보수 월정액 330만원 → 110만원. 신규 고객 확보를 위해 광고비를 월 120만원대 → 270만원대로 확대.
A13: · 2026-06 ~ 08: 최근 3개월 순유출 지속 → 런웨이 약 4~5개월 = 「주의」 구간. 브릿지에서는 금융 분야 지원사업(보증·정책자금)이 연결됩니다.
A15: 시트 설명
A16: · 거래내역: 브릿지가 읽는 원본 시트(첫 시트). 열 = 일자·구분·항목·적요·입금·출금·잔액. 첫 행이 헤더, 2행부터 거래. 잔액은 수식(기초 잔액 + 누적 입금 − 출금).
... A27: · 파일은 브라우저에서만 처리되며 서버에는 월별 합계 등 집계 수치만 전송됩니다. 재무·세무 자문이 아닙니다.
